2020-03-01 21:34:00,372 pypet ERROR    ERROR occurred during a single run! 
Traceback (most recent call last):
  File "/usr/local/lib/python3.7/site-packages/pypet/environment.py", line 259, in _sigint_handling_single_run
    return _single_run(kwargs)
  File "/usr/local/lib/python3.7/site-packages/pypet/environment.py", line 314, in _single_run
    result = runfunc(traj, *runargs, **kwrunparams)
  File "<ipython-input-29-278a4ab4508a>", line 81, in exploreVal
    z = validateMod(4096, lgMult, lgAdd, traj.smMult, traj.smAdd, traj.mu, traj.sigma)
  File "<ipython-input-29-278a4ab4508a>", line 76, in validateMod
    plt.show()
  File "/usr/local/lib/python3.7/site-packages/matplotlib/pyplot.py", line 269, in show
    return _show(*args, **kw)
  File "/usr/local/lib/python3.7/site-packages/ipykernel/pylab/backend_inline.py", line 43, in show
    metadata=_fetch_figure_metadata(figure_manager.canvas.figure)
  File "/usr/local/lib/python3.7/site-packages/IPython/core/display.py", line 313, in display
    format_dict, md_dict = format(obj, include=include, exclude=exclude)
  File "/usr/local/lib/python3.7/site-packages/IPython/core/formatters.py", line 180, in format
    data = formatter(obj)
  File "</usr/local/lib/python3.7/site-packages/decorator.py:decorator-gen-9>", line 2, in __call__
  File "/usr/local/lib/python3.7/site-packages/IPython/core/formatters.py", line 224, in catch_format_error
    r = method(self, *args, **kwargs)
  File "/usr/local/lib/python3.7/site-packages/IPython/core/formatters.py", line 341, in __call__
    return printer(obj)
  File "/usr/local/lib/python3.7/site-packages/IPython/core/pylabtools.py", line 248, in <lambda>
    png_formatter.for_type(Figure, lambda fig: print_figure(fig, 'png', **kwargs))
  File "/usr/local/lib/python3.7/site-packages/IPython/core/pylabtools.py", line 132, in print_figure
    fig.canvas.print_figure(bytes_io, **kw)
  File "/usr/local/lib/python3.7/site-packages/matplotlib/backend_bases.py", line 2069, in print_figure
    bbox_extra_artists=bbox_artists)
  File "/usr/local/lib/python3.7/site-packages/matplotlib/figure.py", line 2367, in get_tightbbox
    bbox = a.get_tightbbox(renderer)
  File "/usr/local/lib/python3.7/site-packages/matplotlib/axes/_base.py", line 4357, in get_tightbbox
    bb_xaxis = self.xaxis.get_tightbbox(renderer)
  File "/usr/local/lib/python3.7/site-packages/matplotlib/axis.py", line 1164, in get_tightbbox
    self._update_label_position(renderer)
  File "/usr/local/lib/python3.7/site-packages/matplotlib/axis.py", line 2014, in _update_label_position
    bboxes, bboxes2 = self._get_tick_boxes_siblings(renderer=renderer)
  File "/usr/local/lib/python3.7/site-packages/matplotlib/axis.py", line 1998, in _get_tick_boxes_siblings
    ticks_to_draw = axx.xaxis._update_ticks()
  File "/usr/local/lib/python3.7/site-packages/matplotlib/axis.py", line 1087, in _update_ticks
    minor_locs = self.get_minorticklocs()
  File "/usr/local/lib/python3.7/site-packages/matplotlib/axis.py", line 1333, in get_minorticklocs
    tr_major_locs = transform.transform(major_locs)
  File "/usr/local/lib/python3.7/site-packages/matplotlib/transforms.py", line 1394, in transform
    res = self.transform_affine(self.transform_non_affine(values))
  File "/usr/local/lib/python3.7/site-packages/matplotlib/scale.py", line 313, in transform_non_affine
    out[a <= 0] = -1000
KeyboardInterrupt
